<?xml version="1.0"?>
<robot xmlns:xacro="http://www.ros.org/wiki/xacro" name="my_robot">

    <link name="footbase_link"/>

    <link name="base_link"/>

        <!-- Fixed joint with offset -->
    <joint name="base_to_offset" type="fixed">
        <parent link="footbase_link"/>
        <child link="base_link"/>
        <origin xyz="0.0 0.0 0.085" rpy="0 0 0"/>  <!-- This is the offset: 10cm forward, 20cm up -->
    </joint>

    <joint name="kropp_joint" type="fixed">
        <parent link="base_link"/>
        <child link="kropp"/>
        <!-- Offset for kropp ift. base_link (brukes til å finjustere modellens referansepunkt). -->
        <origin xyz="0 0.25 0"/>
    </joint>

    <link name="kropp">
        <!-- Kropp: visuell geometri og kollisjon holdes identiske (en boks) for stabil og rask simulering.
             Inertial beregnes via xacro-makro for konsistens når dimensjoner endres. -->
        <visual>
            <origin xyz="0.0 0.0 0.0"/>
            <geometry>
                <box size="0.2 0.3 0.1"/>
            </geometry>
            <material name="white"/>
        </visual>
        <collision>
            <origin xyz="0.0 0.0 0.0"/>
            <geometry>
                <box size="0.2 0.3 0.1"/>
            </geometry>
        </collision>
        <xacro:inertial_box mass="0.5" x="0.2" y="0.3" z="0.1">
            <origin xyz="0 0 0" rpy="0 0 0"/>
        </xacro:inertial_box>
    </link>

    <gazebo reference="kropp">
        <material>Gazebo/White</material>
    </gazebo>

    <!-- Gimbal ("gimble")
         Ønsket: blå stand er fast, og orange boks roterer (yaw rundt Z, pitch rundt X). -->

    <joint name="gimble_stand_joint" type="fixed">
        <parent link="kropp"/>
        <child link="gimble_stand"/>
        <!-- kropp er 0.1 høy (±0.05). Stand er 0.1 lang (±0.05). Senter på stand plasseres derfor på z=0.10. -->
        <origin xyz="0 0 0.10" rpy="0 0 0"/>
    </joint>

    <link name="gimble_stand">
        <visual>
            <geometry>
                <cylinder radius="0.02" length="0.1"/>  
            </geometry>
            <material name="blue"/>
        </visual>
        <collision>
            <geometry>
                <cylinder radius="0.02" length="0.1"/>
            </geometry>
        </collision>
        <xacro:inertial_cylinder mass="0.1" length="0.1" radius="0.02">
            <origin xyz="0 0 0" rpy="0 0 0"/>
        </xacro:inertial_cylinder>
    </link>
    <gazebo reference="gimble_stand">
        <material>Gazebo/Blue</material>
    </gazebo>

    <joint name="gimble_yaw_joint" type="continuous">
        <parent link="gimble_stand"/>
        <child link="gimble_yaw"/>
        <!-- Pivot på toppen av stand (stand topp = +0.05 i stand-rammen). -->
        <origin xyz="0 0 0.05" rpy="0 0 0"/>
        <axis xyz="0 0 1"/>
        <limit effort="1.0" velocity="1.0"/>
    </joint>

    <link name="gimble_yaw">
        <xacro:inertial_sphere mass="0.01" radius="0.01">
            <origin xyz="0 0 0" rpy="0 0 0"/>
        </xacro:inertial_sphere>
    </link>

    <!-- Pitch begrenses til ±15 grader. -->
    <joint name="gimble_pitch_joint" type="revolute">
        <parent link="gimble_yaw"/>
        <child link="lidar"/>
        <origin xyz="0 0 0" rpy="0 0 0"/>
        <axis xyz="1 0 0"/>
        <limit effort="1.0" velocity="1.0" lower="-0.261799" upper="0.261799"/>
    </joint>

</robot>