<?xml version = "1.0"?>
<robot xmlns:xacro="http://www.ros.org/wiki/xacro" name="my_robot">

    <joint name="venstre_hjul_joint" type="continuous">
        <parent link="kropp"/>
        <child link="venstre_hjul"/>
        <origin xyz="-0.1025 0.0 -0.05"/>
        <axis xyz="1 0 0"/>
        <limit effort="1.0" velocity="10.0"/>
    </joint>

    <link name="venstre_hjul">
        <visual>
            <origin rpy="1.57079632679 0 1.57079632679"/>
            <geometry>
                <cylinder radius="0.035" length="0.005"/>
            </geometry>
            <material name="black"/>
        </visual>
        <collision>
            <origin rpy="1.57079632679 0 1.57079632679"/>
            <geometry>
                <cylinder radius="0.035" length="0.005"/>
            </geometry>
        </collision>
        <xacro:inertial_cylinder mass="0.1" length="0.005" radius="0.035">
            <origin xyz="0 0 0" rpy="0 0 0"/>
        </xacro:inertial_cylinder>
    </link>

    <gazebo reference="venstre_hjul">
        <material>Gazebo/Black</material>
    </gazebo>

    <joint name="høyre_hjul_joint" type="continuous">
        <parent link="kropp"/>
        <child link="høyre_hjul"/>
        <origin xyz="0.1025 0 -0.05"/>
        <axis xyz="1 0 0"/>
        <limit effort="1.0" velocity="10.0"/>
    </joint>

    <link name="høyre_hjul">
        <visual>
            <origin rpy="1.57079632679 0 1.57079632679"/>
            <geometry>
                <cylinder radius="0.035" length="0.005"/>
            </geometry>
            <material name="black"/>
        </visual>
        <collision>
            <origin rpy="1.57079632679 0 1.57079632679"/>
            <geometry>
                <cylinder radius="0.035" length="0.005"/>
            </geometry>
        </collision>
        <xacro:inertial_cylinder mass="0.1" length="0.005" radius="0.035">
            <origin xyz="0 0 0" rpy="0 0 0"/>
        </xacro:inertial_cylinder>
    </link>

    <gazebo reference="høyre_hjul">
        <material>Gazebo/Black</material>
    </gazebo>

    <!-- Støttehjul (caster)
         For en enkel plattform brukes et fast montert "kulehjul" (sphere) for stabil støtte.
         Plasser Z slik at støttehjulet berører bakken på samme høyde som drivhjulene. -->

    <joint name="cast_hjul_joint" type="fixed">
        <parent link="kropp"/>
        <child link="cast_hjul"/>
        <origin xyz="0 -0.12 -0.055"/>
    </joint>

    <link name="cast_hjul">
        <visual>
            <geometry>
                <sphere radius="0.03"/>
            </geometry>
            <material name="black"/>
        </visual>
        <collision>
            <geometry>
                <sphere radius="0.03"/>
            </geometry>
        </collision>
        <xacro:inertial_sphere mass="0.1" radius="0.03">
            <origin xyz="0 0 0" rpy="0 0 0"/>
        </xacro:inertial_sphere>
    </link>
    <gazebo reference="cast_hjul">
        <material>Gazebo/Black</material>

        <!--friksjons coff-->
        <mu1 value="0.000001"/>
        <mu2 value="0.000001"/>
    </gazebo>

   

</robot>